<robot name="rizon4s">
    <joint name="joint1" type="revolute">
        <parent link="base_link" />
        <child link="link1" />
        <origin rpy="0.000000000 -0.000000000 -3.141592654" xyz="0.000000 0.000000 0.155000" />
        <axis xyz="0 0 1" />
        <limit effort="123" lower="-2.7925" upper="2.7925" velocity="2.0944" />
    </joint>
    <joint name="joint2" type="revolute">
        <parent link="link1" />
        <child link="link2" />
        <origin rpy="-1.570796327 -0.000000000 0.000000000" xyz="0.000000 0.030000 0.210000" />
        <axis xyz="0 0 1" />
        <limit effort="123" lower="-2.2689" upper="2.2689" velocity="2.0944" />
    </joint>
    <joint name="joint3" type="revolute">
        <parent link="link2" />
        <child link="link3" />
        <origin rpy="0.000000000 -0.000000000 0.000000000" xyz="0.000000 0.035000 0.205000" />
        <axis xyz="0 0 1" />
        <limit effort="64" lower="-2.9671" upper="2.9671" velocity="2.4435" />
    </joint>
    <joint name="joint4" type="revolute">
        <parent link="link3" />
        <child link="link4" />
        <origin rpy="-1.570796327 -0.000000000 -3.141592654" xyz="-0.020000 -0.030000 0.190000" />
        <axis xyz="0 0 1" />
        <limit effort="64" lower="-1.8675" upper="2.6878" velocity="2.4435" />
    </joint>
    <joint name="joint5" type="revolute">
        <parent link="link4" />
        <child link="link5" />
        <origin rpy="0.000000000 -0.000000000 -3.141592654" xyz="-0.020000 0.025000 0.195000" />
        <axis xyz="0 0 1" />
        <limit effort="39" lower="-2.9671" upper="2.9671" velocity="4.8869" />
    </joint>
    <joint name="joint6" type="revolute">
        <parent link="link5" />
        <child link="link6" />
        <origin rpy="-1.570796327 -0.000000000 -0.000000000" xyz="-0.000000 0.030000 0.190000" />
        <axis xyz="0 0 1" />
        <limit effort="39" lower="-1.3963" upper="4.5379" velocity="4.8869" />
    </joint>
    <joint name="joint7" type="revolute">
        <parent link="link6" />
        <child link="link7" />
        <origin rpy="-0.000000000 -1.570796306 0.000000000" xyz="-0.015000 0.073000 0.110000" />
        <axis xyz="0 0 1" />
        <limit effort="39" lower="-2.9671" upper="2.9671" velocity="4.8869" />
    </joint>
    <joint name="EE" type="fixed">
        <parent link="link7" />
        <child link="flange" />
        <origin rpy="0.000000000 0.000000000 -3.141592654" xyz="0.000000 0.000000 0.124000" />
    </joint>
    <link name="base_link">
        <inertial>
            <mass value="3.7" />
            <origin rpy="0 0 0" xyz="0.0 -0.0 0.09" />
            <inertia ixx="0.02" ixy="0.0" ixz="0.0" iyy="0.02" iyz="0.0" izz="0.01" />
        </inertial>
        <visual name="shell">
            <origin rpy="0 0 0" xyz="0 0 0" />
            <geometry>
                <mesh filename="package://meshes/rizon4s/visual/link0.obj" />
            </geometry>
            <material name="rizon_light_grey" />
        </visual>
        <collision name="hull">
            <origin rpy="0 0 0" xyz="0 0 0" />
            <geometry>
                <mesh filename="package://meshes/rizon4s/collision/link0.stl" />
            </geometry>
        </collision>
    </link>
    <link name="link1">
        <inertial>
            <mass value="3.7" />
            <origin rpy="0 0 0" xyz="0.0 0.01 0.15" />
            <inertia ixx="0.03" ixy="0.0" ixz="0.0" iyy="0.03" iyz="0.0" izz="0.01" />
        </inertial>
        <visual name="shell">
            <origin rpy="0 0 0" xyz="0 0 0" />
            <geometry>
                <mesh filename="package://meshes/rizon4s/visual/link1.obj" />
            </geometry>
            <material name="rizon_light_grey" />
        </visual>
        <visual name="ring">
            <origin rpy="0 0 0" xyz="0 0 -0.0025" />
            <geometry>
                <mesh filename="package://meshes/rizon4s/visual/ring.obj" scale="0.062 0.062 0.002" />
            </geometry>
            <material name="rizon_white" />
        </visual>
        <collision name="hull">
            <origin rpy="0 0 0" xyz="0 0 0" />
            <geometry>
                <mesh filename="package://meshes/rizon4s/collision/link1.stl" />
            </geometry>
        </collision>
    </link>
    <link name="link2">
        <inertial>
            <mass value="2.7" />
            <origin rpy="0 0 0" xyz="0.0 0.04 0.1" />
            <inertia ixx="0.02" ixy="0.0" ixz="0.0" iyy="0.02" iyz="-0.0" izz="0.0" />
        </inertial>
        <visual name="shell">
            <origin rpy="0 0 0" xyz="0 0 0" />
            <geometry>
                <mesh filename="package://meshes/rizon4s/visual/link2.obj" />
            </geometry>
            <material name="rizon_light_grey" />
        </visual>
        <visual name="ring">
            <origin rpy="1.5707963 0 0" xyz="0 -0.0025 0" />
            <geometry>
                <mesh filename="package://meshes/rizon4s/visual/ring.obj" scale="0.062 0.062 0.002" />
            </geometry>
            <material name="rizon_white" />
        </visual>
        <collision name="hull">
            <origin rpy="0 0 0" xyz="0 0 0" />
            <geometry>
                <mesh filename="package://meshes/rizon4s/collision/link2.stl" />
            </geometry>
        </collision>
    </link>
    <link name="link3">
        <inertial>
            <mass value="2.4" />
            <origin rpy="0 0 0" xyz="-0.01 -0.0 0.13" />
            <inertia ixx="0.01" ixy="0.0" ixz="-0.0" iyy="0.01" iyz="-0.0" izz="0.0" />
        </inertial>
        <visual name="shell">
            <origin rpy="0 0 0" xyz="0 0 0" />
            <geometry>
                <mesh filename="package://meshes/rizon4s/visual/link3.obj" />
            </geometry>
            <material name="rizon_light_grey" />
        </visual>
        <visual name="ring">
            <origin rpy="0 0 0" xyz="0 0 -0.0025" />
            <geometry>
                <mesh filename="package://meshes/rizon4s/visual/ring.obj" scale="0.051 0.051 0.002" />
            </geometry>
            <material name="rizon_white" />
        </visual>
        <collision name="hull">
            <origin rpy="0 0 0" xyz="0 0 0" />
            <geometry>
                <mesh filename="package://meshes/rizon4s/collision/link3.stl" />
            </geometry>
        </collision>
    </link>
    <link name="link4">
        <inertial>
            <mass value="2.4" />
            <origin rpy="0 0 0" xyz="-0.01 0.03 0.1" />
            <inertia ixx="0.02" ixy="0.0" ixz="-0.0" iyy="0.02" iyz="-0.0" izz="0.0" />
        </inertial>
        <visual name="shell">
            <origin rpy="0 0 0" xyz="0 0 0" />
            <geometry>
                <mesh filename="package://meshes/rizon4s/visual/link4.obj" />
            </geometry>
            <material name="rizon_light_grey" />
        </visual>
        <visual name="ring">
            <origin rpy="1.5707963 0 0" xyz="0 -0.0025 0" />
            <geometry>
                <mesh filename="package://meshes/rizon4s/visual/ring.obj" scale="0.051 0.051 0.002" />
            </geometry>
            <material name="rizon_white" />
        </visual>
        <collision name="hull">
            <origin rpy="0 0 0" xyz="0 0 0" />
            <geometry>
                <mesh filename="package://meshes/rizon4s/collision/link4.stl" />
            </geometry>
        </collision>
    </link>
    <link name="link5">
        <inertial>
            <mass value="2.4" />
            <origin rpy="0 0 0" xyz="-0.0 0.0 0.13" />
            <inertia ixx="0.01" ixy="0.0" ixz="0.0" iyy="0.01" iyz="0.0" izz="0.0" />
        </inertial>
        <visual name="shell">
            <origin rpy="0 0 0" xyz="0 0 0" />
            <geometry>
                <mesh filename="package://meshes/rizon4s/visual/link5.obj" />
            </geometry>
            <material name="rizon_light_grey" />
        </visual>
        <visual name="ring">
            <origin rpy="0 0 0" xyz="0 0 -0.0025" />
            <geometry>
                <mesh filename="package://meshes/rizon4s/visual/ring.obj" scale="0.051 0.051 0.002" />
            </geometry>
            <material name="rizon_white" />
        </visual>
        <collision name="hull">
            <origin rpy="0 0 0" xyz="0 0 0" />
            <geometry>
                <mesh filename="package://meshes/rizon4s/collision/link5.stl" />
            </geometry>
        </collision>
    </link>
    <link name="link6">
        <inertial>
            <mass value="2.2" />
            <origin rpy="0 0 0" xyz="0.02 0.06 0.07" />
            <inertia ixx="0.01" ixy="0.0" ixz="0.0" iyy="0.01" iyz="0.0" izz="0.0" />
        </inertial>
        <visual name="shell">
            <origin rpy="0 0 0" xyz="0 0 0" />
            <geometry>
                <mesh filename="package://meshes/rizon4s/visual/link6.obj" />
            </geometry>
            <material name="rizon_light_grey" />
        </visual>
        <visual name="ring">
            <origin rpy="1.5707963 0 0" xyz="0 -0.0025 0" />
            <geometry>
                <mesh filename="package://meshes/rizon4s/visual/ring.obj" scale="0.051 0.051 0.002" />
            </geometry>
            <material name="rizon_white" />
        </visual>
        <collision name="hull">
            <origin rpy="0 0 0" xyz="0 0 0" />
            <geometry>
                <mesh filename="package://meshes/rizon4s/collision/link6.stl" />
            </geometry>
        </collision>
    </link>
    <link name="link7">
        <inertial>
            <mass value="1.4" />
            <origin rpy="0 0 0" xyz="0.0 0.0 0.05" />
            <inertia ixx="0.0" ixy="0.0" ixz="0.0" iyy="0.0" iyz="0.0" izz="0.0" />
        </inertial>
        <visual name="shell">
            <origin rpy="0 0 0" xyz="0 0 0" />
            <geometry>
                <mesh filename="package://meshes/rizon4s/visual/link7.obj" />
            </geometry>
            <material name="rizon_light_grey" />
        </visual>
        <visual name="ring">
            <origin rpy="0 0 0" xyz="0 0 -0.0025" />
            <geometry>
                <mesh filename="package://meshes/rizon4s/visual/ring.obj" scale="0.051 0.051 0.002" />
            </geometry>
            <material name="rizon_white" />
        </visual>
        <collision name="hull">
            <origin rpy="0 0 0" xyz="0 0 0" />
            <geometry>
                <mesh filename="package://meshes/rizon4s/collision/link7.stl" />
            </geometry>
        </collision>
    </link>

    
    <link name="flange">
        <inertial>
      <origin rpy="0 0 0" xyz="0 0 0.0" />
      <mass value="0.057" />
      <inertia ixx="0.0000354" ixy="0.0" ixz="0.0" iyy="0.0000354" iyz="0.0" izz="0.0000354" />
    </inertial>
    <visual>
      <origin rpy="0 0 0" xyz="0 0 0" />
      <geometry>
        <sphere radius="0.033" />
      </geometry>
      <material name="grey">
        <color rgba="0.8 0.8 0.8 1.0" />
      </material>
    </visual>
    <collision>
      <origin rpy="0 0 0" xyz="0 0 0" />
      <geometry>
        <sphere radius="0.033" />
      </geometry>
      <material name="grey">
        <color rgba="0.8 0.8 0.8 1.0" />
      </material>
    </collision>
    
    <contact>
      <lateral_friction value="1.0" />
      <restitution value="0.5" />
    </contact>
  </link>
    

    <material name="rizon_light_grey">
        <color rgba="0.7 0.7 0.7 1.0" />
    </material>
    <material name="rizon_dark_grey">
        <color rgba="0.4 0.4 0.4 1.0" />
    </material>
    <material name="rizon_white">
        <color rgba="1.0 1.0 1.0 1.0" />
    </material>
</robot>